Workbook

Sheet Summary
A1: Art's-Way Manufacturing (ARTW) — V3 Control-Basis Model
A2: Single control-basis summary, tied to the Part-1 pitch deck. $ in millions unless per-share. Yellow = editable input; everything else is a live formula (recalculates on open).
A4: KEY FACTS (CITED — FY25 10-K / Q1 FY26 10-Q / 2026 DEF 14A)
A5: Current price ($/sh) | B5: 2.58
A6: Shares outstanding (M, basic) | B6: 5.184
A7: Shares fully diluted (M) | B7: 5.684
A8: Net debt ($M) | B8: 6.4
A9: Market cap ($M) | B9: =B5*B6
A10: Enterprise value ($M) | B10: =B9+B8
A11: Book value / share ($) | B11: 2.57
A12: Family voting control | B12: 0.515
A13: Analyst coverage | B13: 0
A15: INTRINSIC VALUE — control basis (live from SOTP)
A16: Scenario | B16: FV / sh ($) | C16: vs price | D16: Prob
A17: Bear | B17: =SOTP!B32 | C17: =B17/$B$5-1 | D17: 0.3 | E17: Base ≈ $2.95–2.96 basic (deck rounds components to $2.95); fully-diluted ≈ $2.70. Asset floor: book $2.57, NCAV $1.08 (Graham tab).
A18: Base | B18: =SOTP!C32 | C18: =B18/$B$5-1 | D18: 0.45
A19: Bull | B19: =SOTP!D32 | C19: =B19/$B$5-1 | D19: 0.25
A20: Probability-weighted | B20: =SUMPRODUCT(B17:B19,D17:D19) | C20: =B20/$B$5-1
A22: SOTP BRIDGE — base ($M)
A23: Building business (DCF / multiple blend) | B23: =SOTP!C14
A24: + Ag assets, after orderly sale | B24: =SOTP!D23
A25: − Net debt | B25: =-B8
A26: Equity ($M) → per share | B26: =B23+B24+B25 | C26: =B26/B6
A28: SEARCH-FUND LBO RETURNS (recommended ~$10M debt / 46% lev; 5-yr; from LBO_Sensitivity)
A29: Scenario | B29: MOIC | C29: IRR
A30: Bear | B30: =LBO_Sensitivity!C7 | C30: =LBO_Sensitivity!D7 | E30: Sponsor equity ≈ $11.6M. Deck slide 9 leads with the bull (≈3.7× / ~30% → ~$43M).
A31: Base | B31: =LBO_Sensitivity!E7 | C31: =LBO_Sensitivity!F7
A32: Bull | B32: =LBO_Sensitivity!G7 | C32: =LBO_Sensitivity!H7
A34: VERDICT
A35: Asymmetric, asset-protected search acquisition. Buy near book on a control basis at ~$2.95 (+14%); the asset floor (book $2.57, NCAV $1.08, both Graham tests pass) caps the downside, and the return is built by the operator (divest farm equipment, repay debt, grow the 17%-margin lab builder). Bear is a bounded, collateral-covered loss; cap leverage near $10M (>55% wipes the bear). Conviction hinges on the undisclosed modular leg-split (data floor).

Sheet SegmentP&L
A1: Segment P&L — Ag Products vs Modular Buildings ($000)
A2: CITED: 10-K Note 17 / prior 10-K. The headline conglomerate optics mask a 17%-margin modular gem averaged with a money-losing ag anchor.
A4: AGRICULTURAL PRODUCTS (the segment to divest)
B5: FY23 | C5: FY24 | D5: FY25 | E5: Note
A6: Revenue | B6: 22467 | C6: 14663 | D6: 12749 | F6: CITED — collapsed -13.1% FY25
A7: Gross profit | B7: 6584 | C7: 4155 | D7: 2977 | F7: CITED — 23.4% GM FY25
A8: gross margin | B8: =B7/B6 | C8: =C7/C6 | D8: =D7/D6 | F8: calc
A9: Operating income (loss) | B9: 664 | C9: -1510 | D9: -1462 | F9: CITED — lost ~$1.5M x2 yrs
A10: operating margin | B10: =B9/B6 | C10: =C9/C6 | D10: =D9/D6 | F10: calc
A11: Total assets | B11: 20754 | C11: 18372 | D11: 19204 | F11: CITED — inventory-heavy anchor
A13: MODULAR BUILDINGS (Art's-Way Scientific — the gem to keep)
B14: FY23 | C14: FY24 | D14: FY25 | E14: Note
A15: Revenue | B15: 7814 | C15: 9836 | D15: 10226 | F15: CITED — rose every yr +4.0% FY25
A16: Gross profit | B16: 2000 | C16: 3155 | D16: 3290 | F16: CITED — 32.2% GM FY25
A17: gross margin | B17: =B16/B15 | C17: =C16/C15 | D17: =D16/D15 | F17: calc
A18: Operating income | B18: 867 | C18: 1971 | D18: 1751 | F18: CITED — 17.1% op margin
A19: operating margin | B19: =B18/B15 | C19: =C18/C15 | D19: =D18/D15 | F19: calc
A20: Total assets | B20: 2593 | C20: 2869 | D20: 3274 | F20: CITED — very asset-light
A21: D&A / capex FY25 | D21: 251 | F21: CITED — capex $222K (light)
A23: ERC NORMALIZATION (consolidated, $000) — the single most important adjustment
B24: FY25 reported | C24: Adjustment | D24: Ex-ERC | E24: Note
A25: Consolidated revenue | B25: 22975 | F25: CITED -6.2%
A26: Consolidated operating income | B26: 289 | F26: CITED — avg of 17% biz + loser
A27: Other income (the ERC) | B27: 1514 | F27: CITED — Employee Retention Credit, vs $3K FY24
A28: Reported net income | B28: 1035 | C28: =-B27 | D28: =B28+C28 | F28: CITED net income is an ERC mirage
A29: Pretax ex-ERC (op inc - interest + true other) | B29: =B26-367 | F29: ~break-even/slight loss (interest $367K)
A30: Operating cash flow FY25 | B30: -904 | F30: CITED negative — ag inventory build (+$1,778K)
A31: Cash income taxes paid FY25 | B31: 13 | F31: CITED ~zero (NOL shield)
A33: LEADING INDICATORS (CITED — strongest filing evidence of momentum)
A34: Modular backlog Feb-2 2025 -> 2026 | B34: $2,403K -> $4,882K (+103%)
A35: Modular backlog as of Apr-7 2026 | B35: $4,513K (+83% YoY)
A36: Q1 FY26 modular revenue | B36: $2,886K vs $2,193K (+31.6%)
A37: Ag Products net backlog 2025 -> 2026 | B37: $3,486K -> $3,224K (-7.5%; beet equip hurt)
A39: Read: Modular revenue rose every year (7.8->9.8->10.2) on ~$3.3M of assets while Ag collapsed (22.5->14.7->12.7) into losses. FY25 net income $1.035M is almost entirely the $1.514M one-time ERC; ex-ERC the company was break-even. The FY25 negative OCF is an AG inventory phenomenon — modular is asset-light and cash-generative (§A6).

Sheet SOTP
A1: Sum-of-the-Parts — carve-out equity (control basis, v3)
A2: Building EV = blend of DCF and multiple methods. Carve-out equity = Building EV + net Ag disposal − net debt. $ in millions.
A4: 1a. BUILDING EV — multiple method
B5: Bear | C5: Base | D5: Bull
A6: Standalone EBITDA used | B6: 1.4 | C6: 1.7 | D6: 2 | F6: EBITDA = seg EBITDA $2.0M − $0.30M standalone corp (v3). Multiple: 8× base (Limbach project-era ~9.5×, constr. median ~10×; project-economics cap < that). 5/8/10×.
A7: EV / EBITDA multiple | B7: 5 | C7: 8 | D7: 10
A8: Building EV (multiple) | B8: =B6*B7 | C8: =C6*C7 | D8: =D6*D7
A10: 1b. BUILDING EV — DCF method (from ModularDCF tab)
A11: Building EV (DCF) | B11: =ModularDCF!B49 | C11: =ModularDCF!C49 | D11: =ModularDCF!D49
A13: 1c. BUILDING EV — blend (deck value)
A14: Building EV = AVG(multiple, DCF) | B14: =AVERAGE(B8,B11) | C14: =AVERAGE(C8,C11) | D14: =AVERAGE(D8,D11) | F14: Base 8× $13.6M & DCF $14.5M → $14.0M (deck slide 10).
A16: 1d. AG DISPOSAL — orderly wind-down (recovery haircuts)
B17: Asset $M | C17: Bear % | D17: Base % | E17: Bull %
A18: Inventory (aged whole-goods) | B18: 9.5 | C18: 0.5 | D18: 0.6 | E18: 0.75
A19: Accounts receivable | B19: 1.6 | C19: 0.85 | D19: 0.95 | E19: 1
A20: PP&E (single-purpose plant) | B20: 4.5 | C20: 0.3 | D20: 0.4 | E20: 0.55
A21: Gross disposal proceeds | C21: =SUMPRODUCT($B18:$B20,C18:C20) | D21: =SUMPRODUCT($B18:$B20,D18:D20) | E21: =SUMPRODUCT($B18:$B20,E18:E20)
A22: less: wind-down cost | C22: -2 | D22: -1.3 | E22: -0.8
A23: Net Ag disposal proceeds | C23: =C21+C22 | D23: =D21+D22 | E23: =E21+E22 | F23: Base $7.7M (reviewer-disciplined; recoveries 60/95/40%).
A25: 1e. SOTP ROLL-UP → carve-out equity / share
B26: Bear | C26: Base | D26: Bull
A27: Building EV (from 1c) | B27: =B14 | C27: =C14 | D27: =D14
A28: + Net Ag disposal (from 1d) | B28: =C23 | C28: =D23 | D28: =E23
A29: − Net debt at close | B29: =Summary!$B$8 | C29: =Summary!$B$8 | D29: =Summary!$B$8
A30: Carve-out equity ($M) | B30: =B27+B28-B29 | C30: =C27+C28-C29 | D30: =D27+D28-D29
A31: Shares (M, basic) | B31: =Summary!$B$6 | C31: =Summary!$B$6 | D31: =Summary!$B$6
A32: FAIR VALUE / SHARE ($) | B32: =B30/B31 | C32: =C30/C31 | D32: =D30/D31
A33: Base ties to deck: $14.0M + $7.7M − $6.4M = $15.3M ÷ 5.184M ≈ $2.95.

Sheet ModularDCF
A1: Standalone Modular (lab-builder) DCF — v3, 3 scenarios ($M, explicit yr 1–7)
A2: v3: WACC 14.0/12.5/11.5; EBITDA margin lifted to 16.6% base (corp-cost add-back $0.45M→$0.30M); near-term cash-tax holiday yrs 1–3 (NOL/§382, base & bull). D&A & capex 2.5% rev (asset-light); ΔWC 10% of incremental rev.
A3: Driver / Year | B3: Bear | C3: Base | D3: Bull
A4: Base-year revenue (FY25 modular) | B4: 10.226 | C4: 10.226 | D4: 10.226
A5: Yr1 revenue growth | B5: -0.1 | C5: 0.08 | D5: 0.18
A6: Yr2 revenue growth | B6: -0.05 | C6: 0.06 | D6: 0.14
A7: Yr3 revenue growth | B7: 0 | C7: 0.05 | D7: 0.1
A8: Yr4 revenue growth | B8: 0.02 | C8: 0.04 | D8: 0.08
A9: Yr5 revenue growth | B9: 0.02 | C9: 0.04 | D9: 0.06
A10: Yr6 revenue growth | B10: 0.02 | C10: 0.035 | D10: 0.05
A11: Yr7 revenue growth | B11: 0.02 | C11: 0.03 | D11: 0.04
A12: EBITDA margin | B12: 0.13 | C12: 0.166 | D12: 0.19
A13: D&A (% revenue) | B13: 0.025 | C13: 0.025 | D13: 0.025
A14: Capex (% revenue) | B14: 0.025 | C14: 0.025 | D14: 0.025
A15: ΔWC (% incremental rev) | B15: 0.1 | C15: 0.1 | D15: 0.1
... A19: Cash tax — yrs 4–7 | B19: 0.15 | C19: 0.15 | D19: 0.15
A21: PROJECTION ($M)
A22: Revenue Yr1 | B22: =B4*(1+B5) | C22: =C4*(1+C5) | D22: =D4*(1+D5)
A23: Revenue Yr2 | B23: =B22*(1+B6) | C23: =C22*(1+C6) | D23: =D22*(1+D6)
A24: Revenue Yr3 | B24: =B23*(1+B7) | C24: =C23*(1+C7) | D24: =D23*(1+D7)
A25: Revenue Yr4 | B25: =B24*(1+B8) | C25: =C24*(1+C8) | D25: =D24*(1+D8)
A26: Revenue Yr5 | B26: =B25*(1+B9) | C26: =C25*(1+C9) | D26: =D25*(1+D9)
A27: Revenue Yr6 | B27: =B26*(1+B10) | C27: =C26*(1+C10) | D27: =D26*(1+D10)
A28: Revenue Yr7 | B28: =B27*(1+B11) | C28: =C27*(1+C11) | D28: =D27*(1+D11)
A29: Free cash flow ($M)
A30: FCF Yr1 | B30: =B22*B$12-B$18*(B22*B$12-B22*B$13)-B22*B$14-B$15*(B22-B4) | C30: =C22*C$12-C$18*(C22*C$12-C22*C$13)-C22*C$14-C$15*(C22-C4) | D30: =D22*D$12-D$18*(D22*D$12-D22*D$13)-D22*D$14-D$15*(D22-D4)
A31: FCF Yr2 | B31: =B23*B$12-B$18*(B23*B$12-B23*B$13)-B23*B$14-B$15*(B23-B22) | C31: =C23*C$12-C$18*(C23*C$12-C23*C$13)-C23*C$14-C$15*(C23-C22) | D31: =D23*D$12-D$18*(D23*D$12-D23*D$13)-D23*D$14-D$15*(D23-D22)
A32: FCF Yr3 | B32: =B24*B$12-B$18*(B24*B$12-B24*B$13)-B24*B$14-B$15*(B24-B23) | C32: =C24*C$12-C$18*(C24*C$12-C24*C$13)-C24*C$14-C$15*(C24-C23) | D32: =D24*D$12-D$18*(D24*D$12-D24*D$13)-D24*D$14-D$15*(D24-D23)
A33: FCF Yr4 | B33: =B25*B$12-B$19*(B25*B$12-B25*B$13)-B25*B$14-B$15*(B25-B24) | C33: =C25*C$12-C$19*(C25*C$12-C25*C$13)-C25*C$14-C$15*(C25-C24) | D33: =D25*D$12-D$19*(D25*D$12-D25*D$13)-D25*D$14-D$15*(D25-D24)
A34: FCF Yr5 | B34: =B26*B$12-B$19*(B26*B$12-B26*B$13)-B26*B$14-B$15*(B26-B25) | C34: =C26*C$12-C$19*(C26*C$12-C26*C$13)-C26*C$14-C$15*(C26-C25) | D34: =D26*D$12-D$19*(D26*D$12-D26*D$13)-D26*D$14-D$15*(D26-D25)
A35: FCF Yr6 | B35: =B27*B$12-B$19*(B27*B$12-B27*B$13)-B27*B$14-B$15*(B27-B26) | C35: =C27*C$12-C$19*(C27*C$12-C27*C$13)-C27*C$14-C$15*(C27-C26) | D35: =D27*D$12-D$19*(D27*D$12-D27*D$13)-D27*D$14-D$15*(D27-D26)
A36: FCF Yr7 | B36: =B28*B$12-B$19*(B28*B$12-B28*B$13)-B28*B$14-B$15*(B28-B27) | C36: =C28*C$12-C$19*(C28*C$12-C28*C$13)-C28*C$14-C$15*(C28-C27) | D36: =D28*D$12-D$19*(D28*D$12-D28*D$13)-D28*D$14-D$15*(D28-D27)
A37: PV of FCF ($M)
A38: PV FCF Yr1 | B38: =B30/(1+B$16)^1 | C38: =C30/(1+C$16)^1 | D38: =D30/(1+D$16)^1
A39: PV FCF Yr2 | B39: =B31/(1+B$16)^2 | C39: =C31/(1+C$16)^2 | D39: =D31/(1+D$16)^2
A40: PV FCF Yr3 | B40: =B32/(1+B$16)^3 | C40: =C32/(1+C$16)^3 | D40: =D32/(1+D$16)^3
A41: PV FCF Yr4 | B41: =B33/(1+B$16)^4 | C41: =C33/(1+C$16)^4 | D41: =D33/(1+D$16)^4
A42: PV FCF Yr5 | B42: =B34/(1+B$16)^5 | C42: =C34/(1+C$16)^5 | D42: =D34/(1+D$16)^5
A43: PV FCF Yr6 | B43: =B35/(1+B$16)^6 | C43: =C35/(1+C$16)^6 | D43: =D35/(1+D$16)^6
A44: PV FCF Yr7 | B44: =B36/(1+B$16)^7 | C44: =C36/(1+C$16)^7 | D44: =D36/(1+D$16)^7
...

Sheet VCP_Waterfall
A1: Value-Creation Waterfall — building business ($M, control basis)
A2: Deck slide 8. Three operator levers the buyer actually builds, plus a smaller market re-rating. Driver assumptions benchmarked in model.md §v4; the high-/low-end leg split is undisclosed (mix lever is an estimate).
A4: Lever | B4: Value add ($M) | C4: Bucket | D4: Driver
A5: Building business today (control basis) | B5: =SOTP!C14
A6: Grow sales | B6: 3.3 | C6: Commercial | D6: Real head of sales lifts growth ~2–3% → ~6–8%/yr (backlog +103% under a part-time president).
A7: Move up-market | B7: 2.4 | C7: Mix shift | D7: Shift to BSL-3/GMP (2–3× $/sq ft) lifts blended op margin ~17% → ~19–21%.
A8: Upsell the installed base | B8: 1.7 | C8: Service tail | D8: Annual re-certification/monitoring resold to 150+ delivered buildings (~$7B fragmented services).
A9: Re-rate (a market call) | B9: 1.5 | C9: Re-rate | D9: Standalone faster-growing biocontainment builder toward ~10× sector median. Sized smallest.
A10: Building business if all four work | B10: =B5+SUM(B6:B9)
A12: Target ties to deck: $14.0M → $22.9M.

Sheet TwoLeg
A1: Two-leg operating model — Art's-Way Scientific standalone
A2: The 60/40 split is ESTIMATED — THE DATA FLOOR (§A3/§10). Below the segment total, everything is estimated from one '+$1.355M ag-building' breadcrumb.
A4: Leg | B4: FY25 rev $M | C4: % of modular | D4: Base near-term growth | E4: Policy macro
A5: Research / biocontainment labs | B5: 6.1 | C5: =B5/B7 | D5: flat-to-+3% -> +5-7% | E5: NIH-uncertainty CHILL (cap struck down Jan-26) -> secular tailwind; pharma/biodefense/DoD/private diagnostics diversify off NIH
A6: Ag / animal-biosecurity buildings | B6: 4.1 | C6: =B6/B7 | D6: +5% then revert +2-3% | E6: USDA up-to-$1B HPAI plan ($500M cost-share @75%) FUNDING NOW; drove FY25 +$1.355M (+49%); event-driven/cyclical
A7: Total modular (cited) | B7: 10.226 | C7: =C5+C6
A9: THE POLICY HEDGE (the most attractive structural feature)
A10: The two legs are NEGATIVELY CORRELATED ON POLICY: when the research leg is chilled by federal-science budget fights, the ag-bio leg is funded by a different federal pocket (USDA biosecurity). A single 'modular farm-building' tag misses this hedge entirely. Blended segment ~32% GM / ~17% op margin (cited), lumpy/project-based. Backlog $4.88M (Feb-26, +103% YoY) underwrites ~6 months visibility.
A14: WHY THE SPLIT IS THE #2 TORNADO DRIVER
A15: The 10-K gives only the modular segment total ($10.226M rev, $1.751M op inc) and the '+$1.355M ag-building' breadcrumb (implies FY24 ag-building base ~$2.77M -> FY25 ag-bio leg ~$4.1M = ~40%). Margins by leg are NOT disclosed; research-lab assumed higher margin (BSL/vivarium, longer cycle), ag-bio lower, blending to the cited 32.2% GM. Closes only with IR/management calls or if ARTW breaks out the legs.

Sheet Graham
A1: Graham 'strong financial condition' test (Defensive Investor)
A2: CITED: FY25 10-K MD&A working-capital table (p.511) + balance sheet / Note 10. Contrast HCKT which FAILED both prongs.
A4: Item | B4: Value | C4: Test | D4: Note
A5: Current assets ($M) | B5: 14.78 | D5: CITED — FY25 balance sheet
A6: Current liabilities ($M) | B6: 6.44 | D6: CITED — implied (WC $8.34M = CA - CL)
A7: Current ratio (Graham test: >= 2.0) | B7: =B5/B6 | C7: =IF(B7>=2,"PASS","FAIL") | D7: CITED 2.30x (FY24 1.98x) — PASSES
A8: Working capital (net current assets, $M) | B8: =B5-B6 | D8: CITED $8.34M (FY24 $6.49M)
A10: Long-term debt ($M) | B10: 2.73 | D10: CITED — LT term loans $2.325M + LT finance lease $0.408M
A11: LT debt <= working capital (Graham test) | B11: =B10/B8 | C11: =IF(B10<=B8,"PASS","FAIL") | D11: LT debt $2.73M <= WC $8.34M — PASSES
A13: RESULT: PASSES BOTH PRONGS.
A14: Unlike HCKT (current ratio 1.88x FAIL; LT debt $78.8M > WC $38.2M FAIL), ARTW has a genuine static balance-sheet floor — the downside is partly asset-backed (inventory + plant + 1.0x book), not carried solely by earning power. Also: NCAV $1.08/sh (~42% of price), book value $2.57 ≈ price (~1.0x book).

Sheet Peers
A1: Peer comp set — multiples behind the SOTP & DCF
A2: Source: data/research/artw/peer_benchmarks.csv. FONR = precedent transaction (the base anchor); WSC = leasing ceiling (not comparable); construction median ~10x.
A4: Ticker | B4: Name | C4: Inclusion | D4: EV/EBITDA | E4: EV/Rev | F4: Rev gr % | G4: EBITDA mgn | H4: Notes
A5: ARTW | B5: Art's-Way Manufacturing | C5: subject | F5: -0.062 | G5: 0.046 | H5: Consolidated. FY25 rev $22.975M; op inc $0.289M; EBITDA approx op inc $0.289M + D&A $0.792M = ~$1.08M (1.06M est). Two segments: Ag Products (loss-making) + Modular Buildings (Art's-Way Scientific, ~17% op margin). FCF negative FY25 (OCF -$0.904M). EV ~$19.85M.
A6: FONR | B6: Fonar Corp | C6: excluded | D6: 8 | E6: 0.94 | H6: EXCLUDED as a reference (v3): Fonar is a diagnostic-imaging (MRI) micro-cap with NO end-market/business-model overlap -- a separately-screened name, not an industry comp. Multiple now anchored on CONSTR (~10.3x) capped by WSC; premium on controlled-company freeze-out comps, not FONR's 31.5%.
A7: WSC | B7: WillScot Holdings | C7: secondary | D7: 12.5 | E7: 3.1 | G7: 0.42 | H7: Modular space LEASING (rental fleet), not project-based custom fabrication. EV/EBITDA 11.7x (5-yr low Dec-2025) to 14.5x LTM; ~3.1x revenue; ~42% EBITDA margin (rental model). SCALE + BUSINESS-MODEL MISMATCH: $2.3B rev, recurring lease revenue, fleet ROIC -- NOT a clean comp for a $10M custom-build job shop. Used only as the directional ceiling for 'modular' and to show why ARTW's project model de
A8: CONSTR | B8: Construction sector median (global) | C8: secondary | D8: 10.3 | G8: 0.07 | H8: Sector reference, not a single name. Global construction EV/EBITDA median ~10.3x (2024). Permanent-modular builders carry ~7% weighted EBITDA margin per McKinsey. Establishes that project-based building/construction trades well below WSC's leasing multiple. ARTW modular at ~17% op margin is ABOVE the sector EBITDA-margin norm -- supports a mid-single-digit to high-single-digit EBITDA multiple for
A9: GVA | B9: Granite Construction | C9: excluded | D9: 9 | E9: 0.9 | G9: 0.095 | H9: EXCLUDED as a direct comp: heavy civil/infrastructure contractor, different end markets, no lab/biocontainment exposure. Listed only to document the broad-contractor multiple band (~0.9x rev, ~9x EBITDA) considered and rejected.
A11: Key: FONR (~7-9x EBITDA, 0.94x rev, 31.5% premium, ~$98.6M) is the closest structural analog (CEO-led take-private of a profitable family-controlled health-adjacent micro-cap) — it anchors BOTH the base multiple AND the acquisition premium. WSC (11.7-14.5x) is a LEASING model (recurring rental ROIC) — used only as the unreachable ceiling for 'modular.' Construction median ~10.3x; permanent-modular ~7% EBITDA margin (McKinsey). ARTW modular ~17% op margin is ABOVE the sector norm -> supports mid-to-high-single-digit EBITDA multiple. US modular construction ~$20.3B (2024), ~4.5-6.2% CAGR.

Sheet Assumptions
A1: Assumptions & judgment log — v3 control basis
A2: How each non-cited input was built. CITED = from filings; ESTIMATED/JUDGMENT = reasoned. Full derivation in model.md §v3a, wacc_research.md, filing_review.md, peer_notes.md.
A4: Input | B4: v3 base | C4: Tier | D4: How constructed / logic
A5: WACC | B5: 12.5% | C5: Built (CAPM + premia) | D5: rf 4.3% + β1.4×ERP 5.0% + ~3% size/illiquidity. Control buyer drops the marketable-minority illiquidity slice (v2 13.5%→12.5%). Bear 14.0% / bull 11.5%.
A6: Modular EV/EBITDA multiple | B6: 8× | C6: Judgment (comps) | D6: Limbach project-era ~9.5×, construction median ~10×; project economics (no recurring/leasing) cap below that. Range 6–9×. Bear 5× / bull 10×.
A7: Standalone modular EBITDA | B7: $1.70M | C7: Built | D7: Segment EBITDA $2.0M − $0.30M standalone corp add-back (take-private removes public-co cost; v2 $0.45M→$0.30M). → DCF margin ~16.6%.
A8: Near-term cash tax | B8: ~0% yrs 1–3 | C8: CITED + judgment | D8: ~$7.1M gross federal NOL, no valuation allowance (filing_review.md); §382 caps usage post-control, so only a modest 3-yr holiday claimed, then 15%. Bear claims none.
A9: Ag inventory recovery | B9: 60% | C9: ESTIMATED | D9: Aged whole-goods into a slow market; beet-equipment hit by Dec-2025 ACS payment cut. 55–65% realistic. Bear 50% / bull 75%.
A10: Ag AR recovery | B10: 95% | C10: ESTIMATED | D10: Trade AR collects near par in an orderly wind-down. Bear 85% / bull 100%.
A11: Ag PP&E recovery | B11: 40% | C11: ESTIMATED | D11: Single-purpose rural-Iowa plant; 2024 Tools real-estate sale a loose datapoint. Bear 30% / bull 55%.
A12: Ag wind-down cost | B12: $1.3M | C12: ESTIMATED | D12: Severance, lease breakage, warranty/dealer tail, transaction. Bear $2.0M / bull $0.8M.
A13: D&A & capex (% rev) | B13: 2.5% each | C13: Judgment | D13: Asset-light modular ($3.3M assets, $0.2M capex on $10.2M rev).
A14: ΔWC (% incremental rev) | B14: 10% | C14: Judgment | D14: Project-timing-driven; nets ~zero over a cycle, not a permanent build.
A15: Terminal growth | B15: 2.5% | C15: Judgment | D15: GDP-ish. Bear 1.0% / bull 3.0%.
... A19: LBO entry premium | B19: ~10% | C19: CITED precedent | D19: Friendly control freeze-out comps (not the v2 31.5% FONR template, which is superseded). Detail in LBO_Returns.

Sheet LBO_Returns
A1: Search-Fund LBO Returns - formula-driven (yellow = inputs)
A3: ASSUMPTIONS
A4: Current price ($/sh) | B4: 2.58
A5: Entry premium | B5: 0.1
A6: Entry price ($/sh) | B6: =B4*(1+B5)
A7: Shares (M) | B7: 5.184
A8: Equity purchase ($M) | B8: =B6*B7
A9: Refinance existing net debt ($M) | B9: 6.4
A10: Transaction fees ($M) | B10: =0.03*B8
A11: TOTAL USES ($M) | B11: =B8+B9+B10
A13: Acquisition debt - ABL+SBA+seller ($M) | B13: 10
A14: Sponsor equity ($M) | B14: =B11-B13
A15: Blended debt rate | B15: 0.0625
A18: BASE CASE - operating & debt schedule (margin 16.6%, exit 7x, ag $7.7M)
A19: Year | C19: Entry(0) | D19: 1 | E19: 2 | F19: 3 | G19: 4 | H19: 5
A20: Revenue growth | D20: 0.08 | E20: 0.06 | F20: 0.05 | G20: 0.04 | H20: 0.04
A21: Revenue ($M) | C21: 10.226 | D21: =C21*(1+D20) | E21: =D21*(1+E20) | F21: =E21*(1+F20) | G21: =F21*(1+G20) | H21: =G21*(1+H20)
A22: EBITDA ($M) | D22: =D21*0.166 | E22: =E21*0.166 | F22: =F21*0.166 | G22: =G21*0.166 | H22: =H21*0.166
A23: EBIT ($M) | D23: =D22-0.025*D21 | E23: =E22-0.025*E21 | F23: =F22-0.025*F21 | G23: =G22-0.025*G21 | H23: =H22-0.025*H21
A24: Cash tax ($M) | D24: 0 | E24: 0 | F24: 0 | G24: =0.21*G23 | H24: =0.21*H23
A25: Capex ($M) | D25: =0.025*D21 | E25: =0.025*E21 | F25: =0.025*F21 | G25: =0.025*G21 | H25: =0.025*H21
A26: Chg Working capital ($M) | D26: =0.10*(D21-C21) | E26: =0.10*(E21-D21) | F26: =0.10*(F21-E21) | G26: =0.10*(G21-F21) | H26: =0.10*(H21-G21)
A27: Unlevered FCF ($M) | D27: =D22-D24-D25-D26 | E27: =E22-E24-E25-E26 | F27: =F22-F24-F25-F26 | G27: =G22-G24-G25-G26 | H27: =H22-H24-H25-H26
A28: Debt - beginning ($M) | D28: =$B$13 | E28: =D33 | F28: =E33 | G28: =F33 | H28: =G33
A29: Interest ($M) | D29: =D28*$B$15 | E29: =E28*$B$15 | F29: =F28*$B$15 | G29: =G28*$B$15 | H29: =H28*$B$15
A30: Ag disposal proceeds ($M) | D30: 7.7 | E30: 0 | F30: 0 | G30: 0 | H30: 0
A31: Cash available ($M) | D31: =D27-D29+D30 | E31: =E27-E29+E30 | F31: =F27-F29+F30 | G31: =G27-G29+G30 | H31: =H27-H29+H30
A32: Debt paydown ($M) | D32: =MIN(D28,MAX(D31,0)) | E32: =MIN(E28,MAX(E31,0)) | F32: =MIN(F28,MAX(F31,0)) | G32: =MIN(G28,MAX(G31,0)) | H32: =MIN(H28,MAX(H31,0))
A33: Debt - ending ($M) | D33: =D28-D32 | E33: =E28-E32 | F33: =F28-F32 | G33: =G28-G32 | H33: =H28-H32
A34: Cash - beginning ($M) | D34: 0 | E34: =D35 | F34: =E35 | G34: =F35 | H34: =G35
A35: Cash - ending ($M) | D35: =D34+(D31-D32) | E35: =E34+(E31-E32) | F35: =F34+(F31-F32) | G35: =G34+(G31-G32) | H35: =H34+(H31-H32)
A38: Exit EV ($M) = Yr5 EBITDA x multiple | B38: =H22*8.0
A39: less ending debt / plus ending cash
A40: Exit equity ($M) | B40: =B38-H33+H35
A41: MOIC | B41: =B40/$B$14
A42: IRR (5-yr) | B42: =IF(B40>0,(B40/$B$14)^(1/5)-1,"neg")
A45: BULL CASE - operating & debt schedule (margin 19.0%, exit 10x, ag $10.4M)
A46: Year | C46: Entry(0) | D46: 1 | E46: 2 | F46: 3 | G46: 4 | H46: 5
A47: Revenue growth | D47: 0.18 | E47: 0.14 | F47: 0.1 | G47: 0.08 | H47: 0.06
A48: Revenue ($M) | C48: 10.226 | D48: =C48*(1+D47) | E48: =D48*(1+E47) | F48: =E48*(1+F47) | G48: =F48*(1+G47) | H48: =G48*(1+H47)
...

Sheet LBO_Sensitivity
A1: LBO Sensitivity & Downside Coverage
A3: LEVERAGE SENSITIVITY (MOIC / IRR; 5-yr hold, entry 10% premium)
A4: Acq debt ($M) | B4: Sponsor eq ($M) | C4: Bear MOIC | D4: Bear IRR | E4: Base MOIC | F4: Base IRR | G4: Bull MOIC | H4: Bull IRR
A5: 14.5 | B5: 7 | C5: -0.2x | D5: wipe | E5: 2.01x | F5: 15% | G5: 5.40x | H5: 40%
A6: 12 | B6: 9.6 | C6: 0.19x | D6: -28% | E6: 1.84x | F6: 13% | G6: 4.29x | H6: 34%
A7: 10 | B7: 11.6 | C7: 0.39x | D7: -17% | E7: 1.73x | F7: 12% | G7: 3.73x | H7: 30%
A8: 8 | B8: 13.6 | C8: 0.53x | D8: -12% | E8: 1.64x | F8: 10% | G8: 3.34x | H8: 27%
A9: Recommended ~$10M (<=50%): bear survives (debt collateral-covered); over $12M wipes the bear.
A11: DOWNSIDE COVERAGE AT CLOSE (bear-liquidation collateral vs entry debt)
A12: Asset | B12: Carrying $M | C12: Bear recovery % | D12: Liquidation $M
A13: Ag inventory | B13: 9.5 | C13: 0.5 | D13: =B13*C13
A14: Accounts receivable | B14: 1.6 | C14: 0.85 | D14: =B14*C14
A15: PP&E (plants/land) | B15: 4.5 | C15: 0.35 | D15: =B15*C15
A16: Modular (going-concern floor) | B16: 7 | C16: 1 | D16: =B16*C16
A17: TOTAL COLLATERAL | D17: =SUM(D13:D16)
A18: Entry debt ($M) | D18: 10
A19: Coverage (x) | D19: =D17/D18
