Workbook

Sheet Summary
A1: Art's-Way Manufacturing (ARTW) — Deep-Flow Carve-Out Valuation
A2: v2 (lead-reviewed) · 2026-05-30 · FY ends Nov-30 · $ in millions unless noted · yellow = editable input
A4: VERDICT
A5: FAIRLY-TO-MODESTLY OVERVALUED on the standalone base (-4%). Not a mispriced free gem (net debt + aged ag inventory mean the modular gem sits at ~6-9x standalone EBITDA inside today's EV, ~7.8x base — fair-to-full). The return lives entirely in the bull tail (+83%) and the family-gated friendly-carve-out option. Real Graham asset floor (passes BOTH tests). At a normal control premium (FONR 31.5%) the base acquisition is underwater (0.73x MOIC).
A7: KEY FACTS (CITED — FY25 10-K / Q1 FY26 10-Q / DEF 14A)
A8: Current price ($) | B8: =Scenarios!B3 | E8: CITED 2026-05
A9: Shares outstanding (M) | B9: 5.184 | E9: CITED DEF 14A Mar-5-26
A10: Market cap ($M) | B10: =B8*B9 | E10: =price x shares
A11: Total debt ($M) | B11: 6.41 | E11: CITED bal sheet + Note 10
A12: less: cash ($M) | B12: 0.005 | E12: CITED near-zero cash
A13: Net debt ($M) | B13: =B11-B12 | E13: =debt - cash
A14: Enterprise value ($M) | B14: =B10+B13 | E14: =mkt cap + net debt
A15: Book value / share ($) | B15: 2.57 | E15: CITED equity $13.306M / 5.184M
A16: Price / book | B16: =B8/B15 | E16: ~1.0x book
A17: Analyst coverage | B17: 0 analysts | E17: CITED — pure orphan micro-cap
A18: Control (McConnell family group) | B18: 0.515 | E18: CITED DEF 14A — friendly deal only
A20: HEADLINE OUTPUTS (live from other tabs)
A21: Base FV / share — Modular DCF blend SOTP (§3) | B21: =Scenarios!B8
A22: Base FV / share — SOTP-multiple (§1c) | B22: =SOTP!C27
A23: Standalone FV / share — BASE (blended) | B23: =Scenarios!B8
A24: Probability-weighted standalone FV / share | B24: =Scenarios!B11
A25: Prob-weighted return vs price (3-yr) | B25: =Scenarios!C11
A26: Acquisition MOIC @ FONR 31.5% premium — BASE | B26: =Scenarios!F8
A27: Acquisition MOIC — BULL | B27: =Scenarios!F9
A29: SCENARIO FAIR VALUES (standalone carve-out, blended DCF + multiple)
A30: Scenario | B30: FV / share | C30: vs price | D30: Probability
A31: Bear | B31: =Scenarios!B7 | C31: =Scenarios!C7 | D31: =Scenarios!E7
A32: Base | B32: =Scenarios!B8 | C32: =Scenarios!C8 | D32: =Scenarios!E8
A33: Bull | B33: =Scenarios!B9 | C33: =Scenarios!C9 | D33: =Scenarios!E9
A35: GRAHAM / BUFFETT VALUE LENSES (live from ValueLenses tab)
A36: EPV modular-only, no growth (loads full net debt) | B36: =ValueLenses!B12
A37: Reverse-DCF implied perpetual FCF growth | B37: =ValueLenses!B20
A38: Owner-earnings yield (on market cap) | B38: =ValueLenses!B28
A39: Graham NCAV / share (net-net floor) | B39: =ValueLenses!B34
A40: Graham strong-financial-condition test (both prongs) | B40: =ValueLenses!C42&" / "&ValueLenses!C45
A42: Read: unlike HCKT (failed both Graham prongs, no asset floor), ARTW PASSES BOTH — a real static balance-sheet floor (NCAV $1.08, book ~1.0x). But the reverse-DCF says ~$20M EV already embeds ~7% perpetual growth: the market is NOT pricing a melting farm-equipment microcap. No margin of safety on the base; the upside is bull-only + the carve-out option.
A45: TABS: Summary · SegmentP&L · SOTP · ModularDCF · TwoLeg · Scenarios · ValueLenses · Graham · Peers · Assumptions

Sheet SegmentP&L
A1: Segment P&L — Ag Products vs Modular Buildings ($000)
A2: CITED: 10-K Note 17 / prior 10-K. The headline conglomerate optics mask a 17%-margin modular gem averaged with a money-losing ag anchor.
A4: AGRICULTURAL PRODUCTS (the segment to divest)
B5: FY23 | C5: FY24 | D5: FY25 | E5: Note
A6: Revenue | B6: 22467 | C6: 14663 | D6: 12749 | F6: CITED — collapsed -13.1% FY25
A7: Gross profit | B7: 6584 | C7: 4155 | D7: 2977 | F7: CITED — 23.4% GM FY25
A8: gross margin | B8: =B7/B6 | C8: =C7/C6 | D8: =D7/D6 | F8: calc
A9: Operating income (loss) | B9: 664 | C9: -1510 | D9: -1462 | F9: CITED — lost ~$1.5M x2 yrs
A10: operating margin | B10: =B9/B6 | C10: =C9/C6 | D10: =D9/D6 | F10: calc
A11: Total assets | B11: 20754 | C11: 18372 | D11: 19204 | F11: CITED — inventory-heavy anchor
A13: MODULAR BUILDINGS (Art's-Way Scientific — the gem to keep)
B14: FY23 | C14: FY24 | D14: FY25 | E14: Note
A15: Revenue | B15: 7814 | C15: 9836 | D15: 10226 | F15: CITED — rose every yr +4.0% FY25
A16: Gross profit | B16: 2000 | C16: 3155 | D16: 3290 | F16: CITED — 32.2% GM FY25
A17: gross margin | B17: =B16/B15 | C17: =C16/C15 | D17: =D16/D15 | F17: calc
A18: Operating income | B18: 867 | C18: 1971 | D18: 1751 | F18: CITED — 17.1% op margin
A19: operating margin | B19: =B18/B15 | C19: =C18/C15 | D19: =D18/D15 | F19: calc
A20: Total assets | B20: 2593 | C20: 2869 | D20: 3274 | F20: CITED — very asset-light
A21: D&A / capex FY25 | D21: 251 | F21: CITED — capex $222K (light)
A23: ERC NORMALIZATION (consolidated, $000) — the single most important adjustment
B24: FY25 reported | C24: Adjustment | D24: Ex-ERC | E24: Note
A25: Consolidated revenue | B25: 22975 | F25: CITED -6.2%
A26: Consolidated operating income | B26: 289 | F26: CITED — avg of 17% biz + loser
A27: Other income (the ERC) | B27: 1514 | F27: CITED — Employee Retention Credit, vs $3K FY24
A28: Reported net income | B28: 1035 | C28: =-B27 | D28: =B28+C28 | F28: CITED net income is an ERC mirage
A29: Pretax ex-ERC (op inc - interest + true other) | B29: =B26-367 | F29: ~break-even/slight loss (interest $367K)
A30: Operating cash flow FY25 | B30: -904 | F30: CITED negative — ag inventory build (+$1,778K)
A31: Cash income taxes paid FY25 | B31: 13 | F31: CITED ~zero (NOL shield)
A33: LEADING INDICATORS (CITED — strongest filing evidence of momentum)
A34: Modular backlog Feb-2 2025 -> 2026 | B34: $2,403K -> $4,882K (+103%)
A35: Modular backlog as of Apr-7 2026 | B35: $4,513K (+83% YoY)
A36: Q1 FY26 modular revenue | B36: $2,886K vs $2,193K (+31.6%)
A37: Ag Products net backlog 2025 -> 2026 | B37: $3,486K -> $3,224K (-7.5%; beet equip hurt)
A39: Read: Modular revenue rose every year (7.8->9.8->10.2) on ~$3.3M of assets while Ag collapsed (22.5->14.7->12.7) into losses. FY25 net income $1.035M is almost entirely the $1.514M one-time ERC; ex-ERC the company was break-even. The FY25 negative OCF is an AG inventory phenomenon — modular is asset-light and cash-generative (§A6).

Sheet SOTP
A1: Sum-of-the-Parts (the centerpiece) — the gem is NOT free
A2: Carve-out equity = Modular standalone EV + net Ag disposal - net debt. Ag disposal & debt netted together (revolver funds ag inventory). $ in millions.
A4: 1a. MODULAR STANDALONE EV (multiple method)
B5: Bear | C5: Base | D5: Bull | E5: Note
A6: Standalone EBITDA used | B6: 1.4 | C6: 1.55 | D6: 2 | F6: ESTIMATED — seg EBITDA $2.0M less ~$0.45M standalone corp
A7: EV / EBITDA multiple | B7: 5 | C7: 7 | D7: 10 | F7: FONR ~7-9x anchor; WSC 11.7-14.5x = unreachable ceiling
A8: Modular EV (multiple) | B8: =B6*B7 | C8: =C6*C7 | D8: =D6*D7 | F8: Bear $7.0M / Base $10.9M / Bull $20.0M
A10: 1b. AG PRODUCTS DISPOSAL (orderly wind-down — recovery haircuts) [v2 re-centered]
A11: Ag assets: inventory ~$9.5M, AR ~$1.6M, PP&E (Armstrong plant) ~$4.5M. All haircuts ESTIMATED.
A12: Recovery on… | B12: Asset $M | C12: Bear % | D12: Base % | E12: Bull %
A13: Inventory (aged whole-goods) | B13: 9.5 | C13: 0.5 | D13: 0.6 | E13: 0.75
A14: Accounts receivable | B14: 1.6 | C14: 0.85 | D14: 0.95 | E14: 1
A15: PP&E (single-purpose plant) | B15: 4.5 | C15: 0.3 | D15: 0.4 | E15: 0.55
A16: Gross disposal proceeds | C16: =SUMPRODUCT($B13:$B15,C13:C15) | D16: =SUMPRODUCT($B13:$B15,D13:D15) | E16: =SUMPRODUCT($B13:$B15,E13:E15)
A17: less: wind-down cost (severance/lease/warranty/txn) | C17: -2 | D17: -1.3 | E17: -0.8
A18: Net Ag disposal proceeds | C18: =C16+C17 | D18: =D16+D17 | E18: =E16+E17 | F18: Base $7.7M (v1 70%->60% recenter, was $8.9M)
A20: 1c. SOTP ROLL-UP — carve-out equity (multiple method)
B21: Bear | C21: Base | D21: Bull | E21: Note
A22: Modular EV (from 1a) | B22: =B8 | C22: =C8 | D22: =D8
A23: + Net Ag disposal (from 1b) | B23: =C18 | C23: =D18 | D23: =E18
A24: - Net debt at close | B24: =$B$28 | C24: =$B$28 | D24: =$B$28
A25: Carve-out equity | B25: =B22+B23-B24 | C25: =C22+C23-C24 | D25: =D22+D23-D24
A26: Shares (M) | B26: =$B$29 | C26: =$B$29 | D26: =$B$29
A27: Value per share ($) — SOTP multiple | B27: =B25/B26 | C27: =C25/C26 | D27: =D25/D26 | F27: Bear $1.16 / Base $2.35 / Bull $4.63
A28: Net debt ($M) | B28: =Summary!B13
A29: Shares (M) | B29: =Summary!B9
A31: 1d. REVERSE-SOTP — is the modular gem free inside today's EV? NO, fair-to-full
A32: Strip net ag disposal out of EV; see what's left implied for modular.
A33: Ag valued at… | B33: Net ag $M | C33: Implied Modular EV | D33: Implied EV/EBITDA
A34: EV today ($M) | B34: =Summary!B14
A35: Base orderly | B35: =D18 | C35: =$B$34-B35 | D35: 7.8
A36: Bull going-concern | B36: =E18 | C36: =$B$34-B36 | D36: 6
A37: Bear liquidation | B37: =C18 | C37: =$B$34-B37 | D37: 9.2
A38: Implied ~6-9.2x standalone EBITDA (~7.8x base) — fair-to-full, not free. Contrast USNA where net cash + the stake ≈ whole market cap and the core came free. Here there is no cash cushion and the ag inventory is largely offset by the debt it financed.

Sheet ModularDCF
A1: Standalone Modular DCF — 3 scenarios ($M, explicit yr1-7)
A2: Cash tax 15% (NOLs finite, §A2). D&A & capex ~2.5% rev (asset-light). ΔWC 10% of incremental rev. NO net debt in EV (debt retired by ag disposal — see SOTP §1c).
A3: Driver / Year | B3: Bear | C3: Base | D3: Bull
A4: Base-year revenue (FY25 modular) | B4: 10.226 | C4: 10.226 | D4: 10.226
A5: Yr1 revenue growth | B5: -0.1 | C5: 0.08 | D5: 0.18
A6: Yr2 revenue growth | B6: -0.05 | C6: 0.06 | D6: 0.14
A7: Yr3 revenue growth | B7: 0 | C7: 0.05 | D7: 0.1
A8: Yr4 revenue growth | B8: 0.02 | C8: 0.04 | D8: 0.08
A9: Yr5 revenue growth | B9: 0.02 | C9: 0.04 | D9: 0.06
A10: Yr6 revenue growth | B10: 0.02 | C10: 0.035 | D10: 0.05
A11: Yr7 revenue growth | B11: 0.02 | C11: 0.03 | D11: 0.04
A12: EBITDA margin | B12: 0.13 | C12: 0.16 | D12: 0.19
A13: D&A (% of revenue) | B13: 0.025 | C13: 0.025 | D13: 0.025
A14: Cash tax rate | B14: 0.15 | C14: 0.15 | D14: 0.15
A15: Capex (% of revenue) | B15: 0.025 | C15: 0.025 | D15: 0.025
... A18: Terminal growth | B18: 0.01 | C18: 0.025 | D18: 0.03
A20: PROJECTION ($M)
A21: Revenue Yr1 | B21: =B4*(1+B5) | C21: =C4*(1+C5) | D21: =D4*(1+D5)
A22: Revenue Yr2 | B22: =B21*(1+B6) | C22: =C21*(1+C6) | D22: =D21*(1+D6)
A23: Revenue Yr3 | B23: =B22*(1+B7) | C23: =C22*(1+C7) | D23: =D22*(1+D7)
A24: Revenue Yr4 | B24: =B23*(1+B8) | C24: =C23*(1+C8) | D24: =D23*(1+D8)
A25: Revenue Yr5 | B25: =B24*(1+B9) | C25: =C24*(1+C9) | D25: =D24*(1+D9)
A26: Revenue Yr6 | B26: =B25*(1+B10) | C26: =C25*(1+C10) | D26: =D25*(1+D10)
A27: Revenue Yr7 | B27: =B26*(1+B11) | C27: =C26*(1+C11) | D27: =D26*(1+D11)
A28: EBITDA
A29: EBITDA Yr1 | B29: =B21*B$12 | C29: =C21*C$12 | D29: =D21*D$12
A30: EBITDA Yr2 | B30: =B22*B$12 | C30: =C22*C$12 | D30: =D22*D$12
A31: EBITDA Yr3 | B31: =B23*B$12 | C31: =C23*C$12 | D31: =D23*D$12
A32: EBITDA Yr4 | B32: =B24*B$12 | C32: =C24*C$12 | D32: =D24*D$12
A33: EBITDA Yr5 | B33: =B25*B$12 | C33: =C25*C$12 | D33: =D25*D$12
A34: EBITDA Yr6 | B34: =B26*B$12 | C34: =C26*C$12 | D34: =D26*D$12
A35: EBITDA Yr7 | B35: =B27*B$12 | C35: =C27*C$12 | D35: =D27*D$12
A36: Free cash flow
A37: FCF Yr1 | B37: =B29-(B29-B21*B$13)*B$14-B21*B$15-(B21-B4)*B$16 | C37: =C29-(C29-C21*C$13)*C$14-C21*C$15-(C21-C4)*C$16 | D37: =D29-(D29-D21*D$13)*D$14-D21*D$15-(D21-D4)*D$16
A38: FCF Yr2 | B38: =B30-(B30-B22*B$13)*B$14-B22*B$15-(B22-B21)*B$16 | C38: =C30-(C30-C22*C$13)*C$14-C22*C$15-(C22-C21)*C$16 | D38: =D30-(D30-D22*D$13)*D$14-D22*D$15-(D22-D21)*D$16
A39: FCF Yr3 | B39: =B31-(B31-B23*B$13)*B$14-B23*B$15-(B23-B22)*B$16 | C39: =C31-(C31-C23*C$13)*C$14-C23*C$15-(C23-C22)*C$16 | D39: =D31-(D31-D23*D$13)*D$14-D23*D$15-(D23-D22)*D$16
A40: FCF Yr4 | B40: =B32-(B32-B24*B$13)*B$14-B24*B$15-(B24-B23)*B$16 | C40: =C32-(C32-C24*C$13)*C$14-C24*C$15-(C24-C23)*C$16 | D40: =D32-(D32-D24*D$13)*D$14-D24*D$15-(D24-D23)*D$16
A41: FCF Yr5 | B41: =B33-(B33-B25*B$13)*B$14-B25*B$15-(B25-B24)*B$16 | C41: =C33-(C33-C25*C$13)*C$14-C25*C$15-(C25-C24)*C$16 | D41: =D33-(D33-D25*D$13)*D$14-D25*D$15-(D25-D24)*D$16
A42: FCF Yr6 | B42: =B34-(B34-B26*B$13)*B$14-B26*B$15-(B26-B25)*B$16 | C42: =C34-(C34-C26*C$13)*C$14-C26*C$15-(C26-C25)*C$16 | D42: =D34-(D34-D26*D$13)*D$14-D26*D$15-(D26-D25)*D$16
A43: FCF Yr7 | B43: =B35-(B35-B27*B$13)*B$14-B27*B$15-(B27-B26)*B$16 | C43: =C35-(C35-C27*C$13)*C$14-C27*C$15-(C27-C26)*C$16 | D43: =D35-(D35-D27*D$13)*D$14-D27*D$15-(D27-D26)*D$16
...

Sheet TwoLeg
A1: Two-leg operating model — Art's-Way Scientific standalone
A2: The 60/40 split is ESTIMATED — THE DATA FLOOR (§A3/§10). Below the segment total, everything is estimated from one '+$1.355M ag-building' breadcrumb.
A4: Leg | B4: FY25 rev $M | C4: % of modular | D4: Base near-term growth | E4: Policy macro
A5: Research / biocontainment labs | B5: 6.1 | C5: =B5/B7 | D5: flat-to-+3% -> +5-7% | E5: NIH-uncertainty CHILL (cap struck down Jan-26) -> secular tailwind; pharma/biodefense/DoD/private diagnostics diversify off NIH
A6: Ag / animal-biosecurity buildings | B6: 4.1 | C6: =B6/B7 | D6: +5% then revert +2-3% | E6: USDA up-to-$1B HPAI plan ($500M cost-share @75%) FUNDING NOW; drove FY25 +$1.355M (+49%); event-driven/cyclical
A7: Total modular (cited) | B7: 10.226 | C7: =C5+C6
A9: THE POLICY HEDGE (the most attractive structural feature)
A10: The two legs are NEGATIVELY CORRELATED ON POLICY: when the research leg is chilled by federal-science budget fights, the ag-bio leg is funded by a different federal pocket (USDA biosecurity). A single 'modular farm-building' tag misses this hedge entirely. Blended segment ~32% GM / ~17% op margin (cited), lumpy/project-based. Backlog $4.88M (Feb-26, +103% YoY) underwrites ~6 months visibility.
A14: WHY THE SPLIT IS THE #2 TORNADO DRIVER
A15: The 10-K gives only the modular segment total ($10.226M rev, $1.751M op inc) and the '+$1.355M ag-building' breadcrumb (implies FY24 ag-building base ~$2.77M -> FY25 ag-bio leg ~$4.1M = ~40%). Margins by leg are NOT disclosed; research-lab assumed higher margin (BSL/vivarium, longer cycle), ag-bio lower, blending to the cited 32.2% GM. Closes only with IR/management calls or if ARTW breaks out the legs.

Sheet Scenarios
A1: Scenarios & returns — standalone FV + acquisition MOIC
A3: Current price ($) | B3: 2.58
A4: Acquisition premium (FONR precedent) | B4: 0.315
A5: Acquisition buy-in price ($) | B5: =B3*(1+B4) | C5: =$3.39/sh at 31.5% premium
A6: STANDALONE CARVE-OUT FAIR VALUE (blended DCF + multiple, §3)
A7: Scenario | B7: FV $/sh | C7: vs price | D7: Acq buy-in $ | E7: Probability | F7: Acq MOIC
A8: Bear | B8: =(((ModularDCF!B56)+(SOTP!B8))/2+SOTP!C18-SOTP!$B$28)/SOTP!$B$29 | C8: =B8/$B$3-1 | D8: =$B$5 | E8: 0.3 | F8: =B8/D8
A9: Base | B9: =(((ModularDCF!C56)+(SOTP!C8))/2+SOTP!D18-SOTP!$B$28)/SOTP!$B$29 | C9: =B9/$B$3-1 | D9: =$B$5 | E9: 0.45 | F9: =B9/D9
A10: Bull | B10: =(((ModularDCF!D56)+(SOTP!D8))/2+SOTP!E18-SOTP!$B$28)/SOTP!$B$29 | C10: =B10/$B$3-1 | D10: =$B$5 | E10: 0.25 | F10: =B10/D10
A11: Probability-weighted | B11: =SUMPRODUCT(B8:B10,E8:E10) | C11: =B11/$B$3-1 | E11: =SUM(E8:E10) | F11: =SUMPRODUCT(F8:F10,E8:E10)
A13: Lead-review anchors: Bear $1.04 (-60%) / Base $2.46 (-4%) / Bull $4.72 (+83%); prob-weighted (30/45/25) ~$2.60 (+1%). Acq MOIC vs $3.39 buy-in: base 0.73x (underwater) / bull 1.39x / bear 0.31x. NOTE: the live bull is ~$4.88 (MOIC 1.44x) — slightly above the anchor because the explicit DCF of model.md's stated bull inputs computes Modular EV ~$22.6M vs model.md's rounded $21.0M (see ModularDCF note). Bear & base tie exactly. The deal still works ONLY on the bull.
A16: Edit column E (probabilities) and any yellow input on ModularDCF/SOTP to flex. FV here = present intrinsic value (gap to fair closes over 3 yrs, no further compounding).

Sheet ValueLenses
A1: Graham / Buffett value lenses ($M unless noted)
A3: EARNINGS POWER VALUE (modular-only, no growth, loads full net debt)
A4: Modular EBIT (op income, normalized) | B4: 1.55
A5: Cash tax rate | B5: 0.15
A6: NOPAT | B6: =B4*(1-B5)
A7: WACC | B7: 0.135
A8: EPV operating (NOPAT / WACC) | B8: =B6/B7
A9: less: net debt | B9: =Summary!B13
A10: EPV equity | B10: =B8-B9
A11: Shares (M) | B11: =Summary!B9
A12: EPV per share ($) | B12: =B10/B11
A13: Read: after loading FULL net debt on modular alone, no-growth value (~$0.65/sh) is well below price — you are paying for growth + the ag asset recovery.
A16: REVERSE DCF (what the ~$20M EV implies)
A17: Enterprise value ($M) | B17: =Summary!B14
A18: Normalized FCF ($M) | B18: 1.2
A19: WACC | B19: 0.135
A20: Implied perpetual FCF growth | B20: =B18-B19/B17
A21: The ~$20M EV embeds ~7% perpetual FCF growth — the market is NOT pricing a melting farm-equipment microcap; it embeds mid-single-digit+ growth. Not cheap on expectations.
A24: OWNER-EARNINGS YIELD (Buffett)
A25: Normalized FCF / owner earnings ($M) | B25: 1.2
A26: Market cap ($M) | B26: =Summary!B10
A27: Owner-earnings yield (on market cap) | B27: =B25/B26
A28: FCF / enterprise value | B28: =B25/Summary!B14
A30: GRAHAM NCAV (net-net floor)
A31: Current assets ($M) | B31: 14.78
A32: less: total liabilities ($M) | B32: 9.17
A33: Net current asset value ($M) | B33: =B31-B32
A34: NCAV per share ($) | B34: =B33/Summary!B9
A35: Not a net-net at $2.58, but ~42% of price covered by net current assets alone — a real downside marker.
A38: GRAHAM STRONG-FINANCIAL-CONDITION (mirror — full calc on Graham tab)
A39: Current ratio | B39: =Graham!B7
A40: LT debt vs working capital | B40: =Graham!B10&" vs "&Graham!B8
A42: Current-ratio test (>=2.0) | C42: =Graham!C7
A45: LT-debt<=WC test | C45: =Graham!C11
A47: PASSES BOTH — unlike HCKT (failed both). A genuine static balance-sheet floor; the downside is partly asset-backed (inventory + plant + 1.0x book), not carried solely by earning power.

Sheet Graham
A1: Graham 'strong financial condition' test (Defensive Investor)
A2: CITED: FY25 10-K MD&A working-capital table (p.511) + balance sheet / Note 10. Contrast HCKT which FAILED both prongs.
A4: Item | B4: Value | C4: Test | D4: Note
A5: Current assets ($M) | B5: 14.78 | D5: CITED — FY25 balance sheet
A6: Current liabilities ($M) | B6: 6.44 | D6: CITED — implied (WC $8.34M = CA - CL)
A7: Current ratio (Graham test: >= 2.0) | B7: =B5/B6 | C7: =IF(B7>=2,"PASS","FAIL") | D7: CITED 2.30x (FY24 1.98x) — PASSES
A8: Working capital (net current assets, $M) | B8: =B5-B6 | D8: CITED $8.34M (FY24 $6.49M)
A10: Long-term debt ($M) | B10: 2.73 | D10: CITED — LT term loans $2.325M + LT finance lease $0.408M
A11: LT debt <= working capital (Graham test) | B11: =B10/B8 | C11: =IF(B10<=B8,"PASS","FAIL") | D11: LT debt $2.73M <= WC $8.34M — PASSES
A13: RESULT: PASSES BOTH PRONGS.
A14: Unlike HCKT (current ratio 1.88x FAIL; LT debt $78.8M > WC $38.2M FAIL), ARTW has a genuine static balance-sheet floor — the downside is partly asset-backed (inventory + plant + 1.0x book), not carried solely by earning power. Also: NCAV $1.08/sh (~42% of price), book value $2.57 ≈ price (~1.0x book).

Sheet Peers
A1: Peer comp set — multiples behind the SOTP & DCF
A2: Source: data/research/artw/peer_benchmarks.csv. FONR = precedent transaction (the base anchor); WSC = leasing ceiling (not comparable); construction median ~10x.
A4: Ticker | B4: Name | C4: Inclusion | D4: EV/EBITDA | E4: EV/Rev | F4: Rev gr % | G4: EBITDA mgn | H4: Notes
A5: ARTW | B5: Art's-Way Manufacturing | C5: subject | F5: -0.062 | G5: 0.046 | H5: Consolidated. FY25 rev $22.975M; op inc $0.289M; EBITDA approx op inc $0.289M + D&A $0.792M = ~$1.08M (1.06M est). Two segments: Ag Products (loss-making) + Modular Buildings (Art's-Way Scientific, ~17% op margin). FCF negative FY25 (OCF -$0.904M). EV ~$19.85M.
A6: FONR | B6: Fonar Corp | C6: precedent_transaction | D6: 8 | E6: 0.94 | H6: PRECEDENT TRANSACTION, not a trading comp. CEO-led take-private at $19.00/sh = ~$98.62M; 31.5% premium to prior close, 39.7% over 90-day avg. Founder/family-controlled, profitable, healthcare-adjacent small-cap. ~0.94x revenue / ~7-9x EBITDA cited. The closest structural analog to an ARTW friendly carve-out/take-private. Anchors the acquisition-premium and small-cap-health multiple.
A7: WSC | B7: WillScot Holdings | C7: secondary | D7: 12.5 | E7: 3.1 | G7: 0.42 | H7: Modular space LEASING (rental fleet), not project-based custom fabrication. EV/EBITDA 11.7x (5-yr low Dec-2025) to 14.5x LTM; ~3.1x revenue; ~42% EBITDA margin (rental model). SCALE + BUSINESS-MODEL MISMATCH: $2.3B rev, recurring lease revenue, fleet ROIC -- NOT a clean comp for a $10M custom-build job shop. Used only as the directional ceiling for 'modular' and to show why ARTW's project model de
A8: CONSTR | B8: Construction sector median (global) | C8: secondary | D8: 10.3 | G8: 0.07 | H8: Sector reference, not a single name. Global construction EV/EBITDA median ~10.3x (2024). Permanent-modular builders carry ~7% weighted EBITDA margin per McKinsey. Establishes that project-based building/construction trades well below WSC's leasing multiple. ARTW modular at ~17% op margin is ABOVE the sector EBITDA-margin norm -- supports a mid-single-digit to high-single-digit EBITDA multiple for
A9: GVA | B9: Granite Construction | C9: excluded | D9: 9 | E9: 0.9 | G9: 0.095 | H9: EXCLUDED as a direct comp: heavy civil/infrastructure contractor, different end markets, no lab/biocontainment exposure. Listed only to document the broad-contractor multiple band (~0.9x rev, ~9x EBITDA) considered and rejected.
A11: Key: FONR (~7-9x EBITDA, 0.94x rev, 31.5% premium, ~$98.6M) is the closest structural analog (CEO-led take-private of a profitable family-controlled health-adjacent micro-cap) — it anchors BOTH the base multiple AND the acquisition premium. WSC (11.7-14.5x) is a LEASING model (recurring rental ROIC) — used only as the unreachable ceiling for 'modular.' Construction median ~10.3x; permanent-modular ~7% EBITDA margin (McKinsey). ARTW modular ~17% op margin is ABOVE the sector norm -> supports mid-to-high-single-digit EBITDA multiple. US modular construction ~$20.3B (2024), ~4.5-6.2% CAGR.

Sheet Assumptions
A1: Assumptions & judgment log — how each non-cited input was built
A3: WACC BUILD (bottom-up CAPM for a micro-cap, project-based, illiquid, single-plant biz)
A4: Risk-free rate (10-yr UST) | B4: 0.043 | D4: CITED — market-observable, May 2026.
A5: Beta (levered) | B5: 1.4 | D5: ESTIMATED — small-cap industrial / project cyclicality; thin-float, don't defend the 2nd digit.
A6: Equity risk premium | B6: 0.055 | D6: ESTIMATED — convention (Damodaran ~4.5-5.5%).
A7: CAPM cost of equity (pre-overlay) | B7: =B4+B5*B6 | D7: =rf + beta x ERP (~12.0%).
A9: Size / illiquidity premium | B9: 0.035 | D9: ESTIMATED — ~$13M cap, float ~2.0M sh, ~$0.1M/day volume. Range 3-4%.
A10: Project-concentration premium | B10: 0 | D10: ESTIMATED — lumpy single-plant project risk; folded into size/illiquidity band here (set 0 to avoid double-count, raise to test).
A11: Cost of equity (CAPM + premia) | B11: =B7+B9+B10 | D11: =CAPM + size/illiquidity + project conc.
A13: WACC — base (applied in DCF) | B13: =B11 | D13: ~13.5% base. Bear 15% (heavier risk premium); bull 12% (cleaner).
A14: WACC — bear | B14: 0.15 | D14: ESTIMATED — heavier risk premium on a missed inflection.
A15: WACC — bull | B15: 0.12 | D15: ESTIMATED — re-rate to a clean biocontainment platform.
A18: JUDGMENT-INPUT LOG (every non-cited assumption: tier + how it was built)
A19: Input | B19: Base | C19: Tier | D19: How constructed / logic
A20: WACC | B20: 13.5% | C20: Built CAPM + premia | D20: rf 4.3% + beta 1.4 x ERP 5.5% + size/illiquidity 3-4%; bear 15% / bull 12% (built above).
A21: Cash tax rate | B21: 15% | C21: Normalized | D21: CITED cash tax ~zero (NOL shield), but NOLs finite & a profitable carve-out exhausts them; do NOT extrapolate 0% (§A2). Near-term real rate lower = upside.
A22: Two-leg split (research/ag-bio) | B22: 60/40 | C22: ESTIMATED — DATA FLOOR | D22: From the single '+$1.355M ag-building' breadcrumb -> FY24 base ~$2.77M -> FY25 ag-bio ~$4.1M (~40%). THE key data-floor assumption (§A3/§10). Revenue & margin by leg NOT disclosed.
A23: Modular standalone EBITDA | B23: $1.55M base | C23: Built | D23: Segment EBITDA $2.002M (op $1.751M + D&A $0.251M) less ~$0.45M incremental standalone public-company/corporate cost. Bear $1.40M / bull $2.00M.
A24: Standalone corporate cost add | B24: $0.45M | C24: ESTIMATED | D24: Only ~$0.18M corp was allocated to modular in the segment table; a standalone registrant carries more. Full take-private removes public-co cost = upside.
A25: Modular EV/EBITDA multiple | B25: 7x base | C25: Judgment | D25: FONR ~7-9x precedent anchor; Porter read supports base 7x and caps bull ~10x. WSC 11.7-14.5x leasing = unreachable ceiling. Bear 5x.
A26: Ag inventory recovery | B26: 60% base | C26: ESTIMATED | D26: v2 re-centered from v1's 70% (which tuned base FV to the $2.58 quote). Aged whole-goods ARTW built into a slow market + beet-equipment hit by Dec-2025 44% ACS payment cut -> 55-65% realistic. Bear 50% / bull 75%.
A27: Ag AR recovery | B27: 95% base | C27: ESTIMATED | D27: Trade AR collects near par in an orderly wind-down. Bear 85% / bull 100%.
A28: Ag PP&E recovery | B28: 40% base | C28: ESTIMATED | D28: Single-purpose rural-Iowa (Armstrong) plant. 2024 Tools real-estate sale $1.8M a loose data point. Bear 30% / bull 55%.
A29: Ag wind-down cost | B29: $1.3M base | C29: ESTIMATED | D29: Severance, lease breakage, warranty/dealer tail, transaction. Bear $2.0M / bull $0.8M.
A30: D&A & capex (% rev) | B30: 2.5% each | C30: Judgment | D30: Asset-light modular ($3.27M assets, $0.222M capex on $10.2M rev).
... A35: Net debt | B35: $6.40M | C35: CITED | D35: Total debt $6.41M (revolver $3.252M + term loans + finance leases, incl ~$0.309M SBA EIDL) - cash $0.005M (§0).
